Workbook

Sheet rIngItem
A1: iiumc-1580 | B1: dword | C1: string[64] | D1: dword | E1: string[64] | F1: dword | G1: dword | H1: dword | I1: string[64] | J1: dword | K1: dword | L1: dword | M1: dword | N1: dword | O1: dword | P1: dword | Q1: dword | R1: dword | S1: dword | T1: dword | U1: dword | V1: float | W1: float | X1: float | Y1: float | Z1: dword | AA1: float | AB1: dword | AC1: float | AD1: dword | AE1: float | AF1: dword | AG1: float | AH1: dword | AI1: dword | AJ1: dword | AK1: dword | AL1: dword | AM1: string[64] | AN1: dword | AO1: dword | AP1: END
A2: iiumc-1579 | B2: IsExist | C2: Model | D2: IconID | E2: Name | F2: KindClt | G2: ItemGrade | H2: FixPart | I2: Civil | J2: LvLim | K2: UpLvLim | L2: ClassGradeLim | M2: Money | N2: StdPrice | O2: StdPoint | P2: GoldPoint | Q2: KillPoint | R2: ProcPoint | S2: StorePrice | T2: IsAbr | U2: EffState | V2: fire | W2: water | X2: soil | Y2: wind | Z2: EffCode1 | AA2: EffUnit1 | AB2: EffCode2 | AC2: EffUnit2 | AD2: EffCode3 | AE2: EffUnit3 | AF2: EffCode4 | AG2: EffUnit4 | AH2: IsSell | AI2: IsExchange | AJ2: IsGround | AK2: IsStore | AL2: IsUseableNormalAcc | AM2: ToolTip | AN2: IsCash | AO2: IsTime
A3: iibba01 | B3: 1 | C3: 700900 | D3: 61 | E3: Fire Parsal WristletA | F3: 9 | G3: 0 | H3: 12 | I3: 11000000 | J3: 1 | K3: -1 | L3: 0 | M3: 1 | N3: 60 | O3: 0 | P3: 0 | Q3: 0 | R3: 0 | S3: 1200 | T3: 0 | U3: 1 | V3: 2 | W3: 0 | X3: 0 | Y3: 0 | Z3: 0 | AA3: 0 | AB3: 0 | AC3: 0 | AD3: 0 | AE3: 0 | AF3: 0 | AG3: 0 | AH3: 1 | AI3: 1 | AJ3: 1 | AK3: 1 | AL3: 1 | AM3: tiibba01 | AN3: 0 | AO3: 0
A4: iibba02 | B4: 1 | C4: 700901 | D4: 61 | E4: Fire Parsal WristletB | F4: 9 | G4: 0 | H4: 12 | I4: 11000000 | J4: 1 | K4: -1 | L4: 0 | M4: 1 | N4: 60 | O4: 0 | P4: 0 | Q4: 0 | R4: 0 | S4: 1200 | T4: 0 | U4: 1 | V4: 3 | W4: 0 | X4: 0 | Y4: 0 | Z4: 0 | AA4: 0 | AB4: 0 | AC4: 0 | AD4: 0 | AE4: 0 | AF4: 0 | AG4: 0 | AH4: 1 | AI4: 1 | AJ4: 1 | AK4: 1 | AL4: 1 | AM4: tiibba02 | AN4: 0 | AO4: 0
A5: iibba03 | B5: 1 | C5: 700902 | D5: 61 | E5: Fire Parsal WristletC | F5: 9 | G5: 0 | H5: 12 | I5: 11000000 | J5: 1 | K5: -1 | L5: 0 | M5: 1 | N5: 60 | O5: 0 | P5: 0 | Q5: 0 | R5: 0 | S5: 1200 | T5: 0 | U5: 1 | V5: 3 | W5: 0 | X5: 0 | Y5: 0 | Z5: 0 | AA5: 0 | AB5: 0 | AC5: 0 | AD5: 0 | AE5: 0 | AF5: 0 | AG5: 0 | AH5: 1 | AI5: 1 | AJ5: 1 | AK5: 1 | AL5: 1 | AM5: tiibba03 | AN5: 0 | AO5: 0
A6: iibba04 | B6: 1 | C6: 700903 | D6: 61 | E6: Fire Parsal WristletD | F6: 9 | G6: 0 | H6: 12 | I6: 11000000 | J6: 1 | K6: -1 | L6: 0 | M6: 1 | N6: 60 | O6: 0 | P6: 0 | Q6: 0 | R6: 0 | S6: 1200 | T6: 0 | U6: 1 | V6: 4 | W6: 0 | X6: 0 | Y6: 0 | Z6: 0 | AA6: 0 | AB6: 0 | AC6: 0 | AD6: 0 | AE6: 0 | AF6: 0 | AG6: 0 | AH6: 1 | AI6: 1 | AJ6: 1 | AK6: 1 | AL6: 1 | AM6: tiibba04 | AN6: 0 | AO6: 0
A7: iibba05 | B7: 1 | C7: 700904 | D7: 61 | E7: Fire Parsal WristletE | F7: 9 | G7: 0 | H7: 12 | I7: 11000000 | J7: 1 | K7: -1 | L7: 0 | M7: 1 | N7: 60 | O7: 0 | P7: 0 | Q7: 0 | R7: 0 | S7: 1200 | T7: 0 | U7: 1 | V7: 5 | W7: 0 | X7: 0 | Y7: 0 | Z7: 0 | AA7: 0 | AB7: 0 | AC7: 0 | AD7: 0 | AE7: 0 | AF7: 0 | AG7: 0 | AH7: 1 | AI7: 1 | AJ7: 1 | AK7: 1 | AL7: 1 | AM7: tiibba05 | AN7: 0 | AO7: 0
A8: iibba06 | B8: 1 | C8: 700905 | D8: 61 | E8: Fire Parsal WristletF | F8: 9 | G8: 0 | H8: 12 | I8: 11000000 | J8: 1 | K8: -1 | L8: 0 | M8: 1 | N8: 60 | O8: 0 | P8: 0 | Q8: 0 | R8: 0 | S8: 1200 | T8: 0 | U8: 1 | V8: 6 | W8: 0 | X8: 0 | Y8: 0 | Z8: 0 | AA8: 0 | AB8: 0 | AC8: 0 | AD8: 0 | AE8: 0 | AF8: 0 | AG8: 0 | AH8: 1 | AI8: 1 | AJ8: 1 | AK8: 1 | AL8: 1 | AM8: tiibba06 | AN8: 0 | AO8: 0
A9: iibba07 | B9: 1 | C9: 700906 | D9: 61 | E9: Fire Parsal WristletG | F9: 9 | G9: 0 | H9: 12 | I9: 11000000 | J9: 1 | K9: -1 | L9: 0 | M9: 1 | N9: 60 | O9: 0 | P9: 0 | Q9: 0 | R9: 0 | S9: 1200 | T9: 0 | U9: 1 | V9: 7 | W9: 0 | X9: 0 | Y9: 0 | Z9: 0 | AA9: 0 | AB9: 0 | AC9: 0 | AD9: 0 | AE9: 0 | AF9: 0 | AG9: 0 | AH9: 1 | AI9: 1 | AJ9: 1 | AK9: 1 | AL9: 1 | AM9: tiibba07 | AN9: 0 | AO9: 0
A10: iibba08 | B10: 1 | C10: 700907 | D10: 62 | E10: Aqua Parsal WristletA | F10: 9 | G10: 0 | H10: 12 | I10: 11000000 | J10: 1 | K10: -1 | L10: 0 | M10: 1 | N10: 60 | O10: 0 | P10: 0 | Q10: 0 | R10: 0 | S10: 1200 | T10: 0 | U10: 1 | V10: 0 | W10: 2 | X10: 0 | Y10: 0 | Z10: 0 | AA10: 0 | AB10: 0 | AC10: 0 | AD10: 0 | AE10: 0 | AF10: 0 | AG10: 0 | AH10: 1 | AI10: 1 | AJ10: 1 | AK10: 1 | AL10: 1 | AM10: tiibba08 | AN10: 0 | AO10: 0
A11: iibba09 | B11: 1 | C11: 700908 | D11: 62 | E11: Aqua Parsal WristletA | F11: 9 | G11: 0 | H11: 12 | I11: 11000000 | J11: 1 | K11: -1 | L11: 0 | M11: 1 | N11: 60 | O11: 0 | P11: 0 | Q11: 0 | R11: 0 | S11: 1200 | T11: 0 | U11: 1 | V11: 0 | W11: 3 | X11: 0 | Y11: 0 | Z11: 0 | AA11: 0 | AB11: 0 | AC11: 0 | AD11: 0 | AE11: 0 | AF11: 0 | AG11: 0 | AH11: 1 | AI11: 1 | AJ11: 1 | AK11: 1 | AL11: 1 | AM11: tiibba09 | AN11: 0 | AO11: 0
A12: iibba10 | B12: 1 | C12: 700909 | D12: 62 | E12: Aqua Parsal WristletB | F12: 9 | G12: 0 | H12: 12 | I12: 11000000 | J12: 1 | K12: -1 | L12: 0 | M12: 1 | N12: 60 | O12: 0 | P12: 0 | Q12: 0 | R12: 0 | S12: 1200 | T12: 0 | U12: 1 | V12: 0 | W12: 3 | X12: 0 | Y12: 0 | Z12: 0 | AA12: 0 | AB12: 0 | AC12: 0 | AD12: 0 | AE12: 0 | AF12: 0 | AG12: 0 | AH12: 1 | AI12: 1 | AJ12: 1 | AK12: 1 | AL12: 1 | AM12: tiibba10 | AN12: 0 | AO12: 0
A13: iibba11 | B13: 1 | C13: 70090A | D13: 62 | E13: Aqua Parsal WristletC | F13: 9 | G13: 0 | H13: 12 | I13: 11000000 | J13: 1 | K13: -1 | L13: 0 | M13: 1 | N13: 60 | O13: 0 | P13: 0 | Q13: 0 | R13: 0 | S13: 1200 | T13: 0 | U13: 1 | V13: 0 | W13: 4 | X13: 0 | Y13: 0 | Z13: 0 | AA13: 0 | AB13: 0 | AC13: 0 | AD13: 0 | AE13: 0 | AF13: 0 | AG13: 0 | AH13: 1 | AI13: 1 | AJ13: 1 | AK13: 1 | AL13: 1 | AM13: tiibba11 | AN13: 0 | AO13: 0
A14: iibba12 | B14: 1 | C14: 70090B | D14: 62 | E14: Aqua Parsal WristletD | F14: 9 | G14: 0 | H14: 12 | I14: 11000000 | J14: 1 | K14: -1 | L14: 0 | M14: 1 | N14: 60 | O14: 0 | P14: 0 | Q14: 0 | R14: 0 | S14: 1200 | T14: 0 | U14: 1 | V14: 0 | W14: 5 | X14: 0 | Y14: 0 | Z14: 0 | AA14: 0 | AB14: 0 | AC14: 0 | AD14: 0 | AE14: 0 | AF14: 0 | AG14: 0 | AH14: 1 | AI14: 1 | AJ14: 1 | AK14: 1 | AL14: 1 | AM14: tiibba12 | AN14: 0 | AO14: 0
... A1592: iicsa32 | B1592: 1 | C1592: A00947 | D1592: 215 | E1592: Solo Boss Ring | F1592: 9 | G1592: 7 | H1592: 12 | I1592: 11111000 | J1592: 1 | K1592: -1 | L1592: 0 | M1592: 0 | N1592: 1 | O1592: 0 | P1592: 0 | Q1592: 0 | R1592: 0 | S1592: 20000 | T1592: 0 | U1592: 1 | V1592: 4 | W1592: 4 | X1592: 4 | Y1592: 4 | Z1592: 6 | AA1592: 0.1 | AB1592: 7 | AC1592: 0.10000001 | AD1592: 5 | AE1592: 0.050000006 | AF1592: 0 | AG1592: 0 | AH1592: 1 | AI1592: 1 | AJ1592: 1 | AK1592: 1 | AL1592: 1 | AM1592: tiicsa28 | AN1592: 1 | AO1592: 1

Sheet 9decrypt
A1: clcode | B1: string[64] | C1: xeh | D1: dword | E1: stb | F1: byte | G1: byte | H1: word | I1: dword | J1: dword | K1: dword | L1: dword | M1: dword | N1: dword | O1: dword | P1: dword | Q1: dword | R1: dword | S1: dword | T1: dword | U1: dword | V1: dword | W1: long | X1: dword | Y1: dword | Z1: dword | AA1: dword | AB1: dword | AC1: byte | AD1: byte | AE1: byte | AF1: byte | AG1: byte | AH1: byte | AI1: byte | AJ1: byte | AK1: dword | AL1: byte | AM1: byte | AN1: byte | AO1: byte | AP1: byte | AQ1: byte | AR1: byte | AS1: byte | AT1: float | AU1: float | AV1: float | AW1: float | AX1: dword | AY1: dword | AZ1: word | BA1: word | BB1: word | BC1: word | BD1: dword | BE1: END
A2: =rIngItem!A2 -> iiumc-1579 | B2: =rIngItem!E2 -> Name | C2: =rIngItem!C2 -> Model | D2: =rIngItem!D2 -> IconID | E2: =rIngItem!I2 -> Civil | F2: ListID | G2: =rIngItem!M2 -> Money | H2: none | I2: =rIngItem!N2 -> StdPrice | J2: =rIngItem!O2 -> StdPoint | K2: =rIngItem!P2 -> GoldPoint | L2: =rIngItem!R2 -> ProcPoint | M2: =rIngItem!Q2 -> KillPoint | N2: =rIngItem!S2 -> StorePrice | O2: =rIngItem!AI2 -> IsExchange | P2: =rIngItem!AH2 -> IsSell | Q2: =rIngItem!AJ2 -> IsGround | R2: =rIngItem!AK2 -> IsStore | S2: Descripton | T2: =rIngItem!B2 -> IsExist | U2: =rIngItem!AN2 -> IsCash | V2: =rIngItem!AO2 -> IsTime | W2: =rIngItem!K2 -> UpLvLim | X2: =rIngItem!G2 -> ItemGrade | Y2: 25 | Z2: none | AA2: 27 | AB2: none | AC2: =rIngItem!J2 -> LvLim | AD2: none | AE2: none | AF2: none | AG2: none | AH2: none | AI2: none | AJ2: none | AK2: none | AL2: EffNum | AM2: =rIngItem!Z2 -> EffCode1 | AN2: =rIngItem!AB2 -> EffCode2 | AO2: =rIngItem!AD2 -> EffCode3 | AP2: =rIngItem!AF2 -> EffCode4 | AQ2: none | AR2: none | AS2: none | AT2: =rIngItem!AA2 -> EffUnit1 | AU2: =rIngItem!AC2 -> EffUnit2 | AV2: =rIngItem!AE2 -> EffUnit3 | AW2: =rIngItem!AG2 -> EffUnit4 | AX2: none | AY2: =rIngItem!L2 -> ClassGradeLim | AZ2: =rIngItem!V2 -> fire | BA2: =rIngItem!W2 -> water | BB2: =rIngItem!X2 -> soil | BC2: =rIngItem!Y2 -> wind | BD2: none
A3: =rIngItem!A3 -> iibba01 | B3: =rIngItem!E3 -> Fire Parsal WristletA | C3: =rIngItem!C3 -> 700900 | D3: =rIngItem!D3 -> 61 | E3: =rIngItem!I3 -> 11000000 | F3: 9 | G3: =rIngItem!M3 -> 1 | H3: 0 | I3: =rIngItem!N3 -> 60 | J3: =rIngItem!O3 -> 0 | K3: =rIngItem!P3 -> 0 | L3: =rIngItem!R3 -> 0 | M3: =rIngItem!Q3 -> 0 | N3: =rIngItem!S3 -> 1200 | O3: =rIngItem!AI3 -> 1 | P3: =rIngItem!AH3 -> 1 | Q3: =rIngItem!AJ3 -> 1 | R3: =rIngItem!AK3 -> 1 | S3: 114 | T3: =rIngItem!B3 -> 1 | U3: =rIngItem!AN3 -> 0 | V3: =rIngItem!AO3 -> 0 | W3: =rIngItem!K3 -> -1 | X3: =rIngItem!G3 -> 0 | Y3: 0 | Z3: 0 | AA3: 0 | AB3: 0 | AC3: =rIngItem!J3 -> 1 | AD3: 0 | AE3: 0 | AF3: 0 | AG3: 0 | AH3: 0 | AI3: 0 | AJ3: 0 | AK3: 0 | AL3: =IF(AM3=0,0,IF(AN3=0,1,IF(AO3=0,2,IF(AP3=0,3,4)))) -> 0 | AM3: =rIngItem!Z3 -> 0 | AN3: =rIngItem!AB3 -> 0 | AO3: =rIngItem!AD3 -> 0 | AP3: =rIngItem!AF3 -> 0 | AQ3: 0 | AR3: 0 | AS3: 0 | AT3: =rIngItem!AA3 -> 0 | AU3: =rIngItem!AC3 -> 0 | AV3: =rIngItem!AE3 -> 0 | AW3: =rIngItem!AG3 -> 0 | AX3: 0 | AY3: =rIngItem!L3 -> 0 | AZ3: =rIngItem!V3 -> 2 | BA3: =rIngItem!W3 -> 0 | BB3: =rIngItem!X3 -> 0 | BC3: =rIngItem!Y3 -> 0 | BD3: 0
A4: =rIngItem!A4 -> iibba02 | B4: =rIngItem!E4 -> Fire Parsal WristletB | C4: =rIngItem!C4 -> 700901 | D4: =rIngItem!D4 -> 61 | E4: =rIngItem!I4 -> 11000000 | F4: 9 | G4: =rIngItem!M4 -> 1 | H4: 0 | I4: =rIngItem!N4 -> 60 | J4: =rIngItem!O4 -> 0 | K4: =rIngItem!P4 -> 0 | L4: =rIngItem!R4 -> 0 | M4: =rIngItem!Q4 -> 0 | N4: =rIngItem!S4 -> 1200 | O4: =rIngItem!AI4 -> 1 | P4: =rIngItem!AH4 -> 1 | Q4: =rIngItem!AJ4 -> 1 | R4: =rIngItem!AK4 -> 1 | S4: 115 | T4: =rIngItem!B4 -> 1 | U4: =rIngItem!AN4 -> 0 | V4: =rIngItem!AO4 -> 0 | W4: =rIngItem!K4 -> -1 | X4: =rIngItem!G4 -> 0 | Y4: 0 | Z4: 0 | AA4: 0 | AB4: 0 | AC4: =rIngItem!J4 -> 1 | AD4: 0 | AE4: 0 | AF4: 0 | AG4: 0 | AH4: 0 | AI4: 0 | AJ4: 0 | AK4: 0 | AL4: =IF(AM4=0,0,IF(AN4=0,1,IF(AO4=0,2,IF(AP4=0,3,4)))) -> 0 | AM4: =rIngItem!Z4 -> 0 | AN4: =rIngItem!AB4 -> 0 | AO4: =rIngItem!AD4 -> 0 | AP4: =rIngItem!AF4 -> 0 | AQ4: 0 | AR4: 0 | AS4: 0 | AT4: =rIngItem!AA4 -> 0 | AU4: =rIngItem!AC4 -> 0 | AV4: =rIngItem!AE4 -> 0 | AW4: =rIngItem!AG4 -> 0 | AX4: 0 | AY4: =rIngItem!L4 -> 0 | AZ4: =rIngItem!V4 -> 3 | BA4: =rIngItem!W4 -> 0 | BB4: =rIngItem!X4 -> 0 | BC4: =rIngItem!Y4 -> 0 | BD4: 0
A5: =rIngItem!A5 -> iibba03 | B5: =rIngItem!E5 -> Fire Parsal WristletC | C5: =rIngItem!C5 -> 700902 | D5: =rIngItem!D5 -> 61 | E5: =rIngItem!I5 -> 11000000 | F5: 9 | G5: =rIngItem!M5 -> 1 | H5: 0 | I5: =rIngItem!N5 -> 60 | J5: =rIngItem!O5 -> 0 | K5: =rIngItem!P5 -> 0 | L5: =rIngItem!R5 -> 0 | M5: =rIngItem!Q5 -> 0 | N5: =rIngItem!S5 -> 1200 | O5: =rIngItem!AI5 -> 1 | P5: =rIngItem!AH5 -> 1 | Q5: =rIngItem!AJ5 -> 1 | R5: =rIngItem!AK5 -> 1 | S5: 116 | T5: =rIngItem!B5 -> 1 | U5: =rIngItem!AN5 -> 0 | V5: =rIngItem!AO5 -> 0 | W5: =rIngItem!K5 -> -1 | X5: =rIngItem!G5 -> 0 | Y5: 0 | Z5: 0 | AA5: 0 | AB5: 0 | AC5: =rIngItem!J5 -> 1 | AD5: 0 | AE5: 0 | AF5: 0 | AG5: 0 | AH5: 0 | AI5: 0 | AJ5: 0 | AK5: 0 | AL5: =IF(AM5=0,0,IF(AN5=0,1,IF(AO5=0,2,IF(AP5=0,3,4)))) -> 0 | AM5: =rIngItem!Z5 -> 0 | AN5: =rIngItem!AB5 -> 0 | AO5: =rIngItem!AD5 -> 0 | AP5: =rIngItem!AF5 -> 0 | AQ5: 0 | AR5: 0 | AS5: 0 | AT5: =rIngItem!AA5 -> 0 | AU5: =rIngItem!AC5 -> 0 | AV5: =rIngItem!AE5 -> 0 | AW5: =rIngItem!AG5 -> 0 | AX5: 0 | AY5: =rIngItem!L5 -> 0 | AZ5: =rIngItem!V5 -> 3 | BA5: =rIngItem!W5 -> 0 | BB5: =rIngItem!X5 -> 0 | BC5: =rIngItem!Y5 -> 0 | BD5: 0
A6: =rIngItem!A6 -> iibba04 | B6: =rIngItem!E6 -> Fire Parsal WristletD | C6: =rIngItem!C6 -> 700903 | D6: =rIngItem!D6 -> 61 | E6: =rIngItem!I6 -> 11000000 | F6: 9 | G6: =rIngItem!M6 -> 1 | H6: 0 | I6: =rIngItem!N6 -> 60 | J6: =rIngItem!O6 -> 0 | K6: =rIngItem!P6 -> 0 | L6: =rIngItem!R6 -> 0 | M6: =rIngItem!Q6 -> 0 | N6: =rIngItem!S6 -> 1200 | O6: =rIngItem!AI6 -> 1 | P6: =rIngItem!AH6 -> 1 | Q6: =rIngItem!AJ6 -> 1 | R6: =rIngItem!AK6 -> 1 | S6: 117 | T6: =rIngItem!B6 -> 1 | U6: =rIngItem!AN6 -> 0 | V6: =rIngItem!AO6 -> 0 | W6: =rIngItem!K6 -> -1 | X6: =rIngItem!G6 -> 0 | Y6: 0 | Z6: 0 | AA6: 0 | AB6: 0 | AC6: =rIngItem!J6 -> 1 | AD6: 0 | AE6: 0 | AF6: 0 | AG6: 0 | AH6: 0 | AI6: 0 | AJ6: 0 | AK6: 0 | AL6: =IF(AM6=0,0,IF(AN6=0,1,IF(AO6=0,2,IF(AP6=0,3,4)))) -> 0 | AM6: =rIngItem!Z6 -> 0 | AN6: =rIngItem!AB6 -> 0 | AO6: =rIngItem!AD6 -> 0 | AP6: =rIngItem!AF6 -> 0 | AQ6: 0 | AR6: 0 | AS6: 0 | AT6: =rIngItem!AA6 -> 0 | AU6: =rIngItem!AC6 -> 0 | AV6: =rIngItem!AE6 -> 0 | AW6: =rIngItem!AG6 -> 0 | AX6: 0 | AY6: =rIngItem!L6 -> 0 | AZ6: =rIngItem!V6 -> 4 | BA6: =rIngItem!W6 -> 0 | BB6: =rIngItem!X6 -> 0 | BC6: =rIngItem!Y6 -> 0 | BD6: 0
A7: =rIngItem!A7 -> iibba05 | B7: =rIngItem!E7 -> Fire Parsal WristletE | C7: =rIngItem!C7 -> 700904 | D7: =rIngItem!D7 -> 61 | E7: =rIngItem!I7 -> 11000000 | F7: 9 | G7: =rIngItem!M7 -> 1 | H7: 0 | I7: =rIngItem!N7 -> 60 | J7: =rIngItem!O7 -> 0 | K7: =rIngItem!P7 -> 0 | L7: =rIngItem!R7 -> 0 | M7: =rIngItem!Q7 -> 0 | N7: =rIngItem!S7 -> 1200 | O7: =rIngItem!AI7 -> 1 | P7: =rIngItem!AH7 -> 1 | Q7: =rIngItem!AJ7 -> 1 | R7: =rIngItem!AK7 -> 1 | S7: 118 | T7: =rIngItem!B7 -> 1 | U7: =rIngItem!AN7 -> 0 | V7: =rIngItem!AO7 -> 0 | W7: =rIngItem!K7 -> -1 | X7: =rIngItem!G7 -> 0 | Y7: 0 | Z7: 0 | AA7: 0 | AB7: 0 | AC7: =rIngItem!J7 -> 1 | AD7: 0 | AE7: 0 | AF7: 0 | AG7: 0 | AH7: 0 | AI7: 0 | AJ7: 0 | AK7: 0 | AL7: =IF(AM7=0,0,IF(AN7=0,1,IF(AO7=0,2,IF(AP7=0,3,4)))) -> 0 | AM7: =rIngItem!Z7 -> 0 | AN7: =rIngItem!AB7 -> 0 | AO7: =rIngItem!AD7 -> 0 | AP7: =rIngItem!AF7 -> 0 | AQ7: 0 | AR7: 0 | AS7: 0 | AT7: =rIngItem!AA7 -> 0 | AU7: =rIngItem!AC7 -> 0 | AV7: =rIngItem!AE7 -> 0 | AW7: =rIngItem!AG7 -> 0 | AX7: 0 | AY7: =rIngItem!L7 -> 0 | AZ7: =rIngItem!V7 -> 5 | BA7: =rIngItem!W7 -> 0 | BB7: =rIngItem!X7 -> 0 | BC7: =rIngItem!Y7 -> 0 | BD7: 0
A8: =rIngItem!A8 -> iibba06 | B8: =rIngItem!E8 -> Fire Parsal WristletF | C8: =rIngItem!C8 -> 700905 | D8: =rIngItem!D8 -> 61 | E8: =rIngItem!I8 -> 11000000 | F8: 9 | G8: =rIngItem!M8 -> 1 | H8: 0 | I8: =rIngItem!N8 -> 60 | J8: =rIngItem!O8 -> 0 | K8: =rIngItem!P8 -> 0 | L8: =rIngItem!R8 -> 0 | M8: =rIngItem!Q8 -> 0 | N8: =rIngItem!S8 -> 1200 | O8: =rIngItem!AI8 -> 1 | P8: =rIngItem!AH8 -> 1 | Q8: =rIngItem!AJ8 -> 1 | R8: =rIngItem!AK8 -> 1 | S8: 119 | T8: =rIngItem!B8 -> 1 | U8: =rIngItem!AN8 -> 0 | V8: =rIngItem!AO8 -> 0 | W8: =rIngItem!K8 -> -1 | X8: =rIngItem!G8 -> 0 | Y8: 0 | Z8: 0 | AA8: 0 | AB8: 0 | AC8: =rIngItem!J8 -> 1 | AD8: 0 | AE8: 0 | AF8: 0 | AG8: 0 | AH8: 0 | AI8: 0 | AJ8: 0 | AK8: 0 | AL8: =IF(AM8=0,0,IF(AN8=0,1,IF(AO8=0,2,IF(AP8=0,3,4)))) -> 0 | AM8: =rIngItem!Z8 -> 0 | AN8: =rIngItem!AB8 -> 0 | AO8: =rIngItem!AD8 -> 0 | AP8: =rIngItem!AF8 -> 0 | AQ8: 0 | AR8: 0 | AS8: 0 | AT8: =rIngItem!AA8 -> 0 | AU8: =rIngItem!AC8 -> 0 | AV8: =rIngItem!AE8 -> 0 | AW8: =rIngItem!AG8 -> 0 | AX8: 0 | AY8: =rIngItem!L8 -> 0 | AZ8: =rIngItem!V8 -> 6 | BA8: =rIngItem!W8 -> 0 | BB8: =rIngItem!X8 -> 0 | BC8: =rIngItem!Y8 -> 0 | BD8: 0
A9: =rIngItem!A9 -> iibba07 | B9: =rIngItem!E9 -> Fire Parsal WristletG | C9: =rIngItem!C9 -> 700906 | D9: =rIngItem!D9 -> 61 | E9: =rIngItem!I9 -> 11000000 | F9: 9 | G9: =rIngItem!M9 -> 1 | H9: 0 | I9: =rIngItem!N9 -> 60 | J9: =rIngItem!O9 -> 0 | K9: =rIngItem!P9 -> 0 | L9: =rIngItem!R9 -> 0 | M9: =rIngItem!Q9 -> 0 | N9: =rIngItem!S9 -> 1200 | O9: =rIngItem!AI9 -> 1 | P9: =rIngItem!AH9 -> 1 | Q9: =rIngItem!AJ9 -> 1 | R9: =rIngItem!AK9 -> 1 | S9: 120 | T9: =rIngItem!B9 -> 1 | U9: =rIngItem!AN9 -> 0 | V9: =rIngItem!AO9 -> 0 | W9: =rIngItem!K9 -> -1 | X9: =rIngItem!G9 -> 0 | Y9: 0 | Z9: 0 | AA9: 0 | AB9: 0 | AC9: =rIngItem!J9 -> 1 | AD9: 0 | AE9: 0 | AF9: 0 | AG9: 0 | AH9: 0 | AI9: 0 | AJ9: 0 | AK9: 0 | AL9: =IF(AM9=0,0,IF(AN9=0,1,IF(AO9=0,2,IF(AP9=0,3,4)))) -> 0 | AM9: =rIngItem!Z9 -> 0 | AN9: =rIngItem!AB9 -> 0 | AO9: =rIngItem!AD9 -> 0 | AP9: =rIngItem!AF9 -> 0 | AQ9: 0 | AR9: 0 | AS9: 0 | AT9: =rIngItem!AA9 -> 0 | AU9: =rIngItem!AC9 -> 0 | AV9: =rIngItem!AE9 -> 0 | AW9: =rIngItem!AG9 -> 0 | AX9: 0 | AY9: =rIngItem!L9 -> 0 | AZ9: =rIngItem!V9 -> 7 | BA9: =rIngItem!W9 -> 0 | BB9: =rIngItem!X9 -> 0 | BC9: =rIngItem!Y9 -> 0 | BD9: 0
A10: =rIngItem!A10 -> iibba08 | B10: =rIngItem!E10 -> Aqua Parsal WristletA | C10: =rIngItem!C10 -> 700907 | D10: =rIngItem!D10 -> 62 | E10: =rIngItem!I10 -> 11000000 | F10: 9 | G10: =rIngItem!M10 -> 1 | H10: 0 | I10: =rIngItem!N10 -> 60 | J10: =rIngItem!O10 -> 0 | K10: =rIngItem!P10 -> 0 | L10: =rIngItem!R10 -> 0 | M10: =rIngItem!Q10 -> 0 | N10: =rIngItem!S10 -> 1200 | O10: =rIngItem!AI10 -> 1 | P10: =rIngItem!AH10 -> 1 | Q10: =rIngItem!AJ10 -> 1 | R10: =rIngItem!AK10 -> 1 | S10: 121 | T10: =rIngItem!B10 -> 1 | U10: =rIngItem!AN10 -> 0 | V10: =rIngItem!AO10 -> 0 | W10: =rIngItem!K10 -> -1 | X10: =rIngItem!G10 -> 0 | Y10: 0 | Z10: 0 | AA10: 0 | AB10: 0 | AC10: =rIngItem!J10 -> 1 | AD10: 0 | AE10: 0 | AF10: 0 | AG10: 0 | AH10: 0 | AI10: 0 | AJ10: 0 | AK10: 0 | AL10: =IF(AM10=0,0,IF(AN10=0,1,IF(AO10=0,2,IF(AP10=0,3,4)))) -> 0 | AM10: =rIngItem!Z10 -> 0 | AN10: =rIngItem!AB10 -> 0 | AO10: =rIngItem!AD10 -> 0 | AP10: =rIngItem!AF10 -> 0 | AQ10: 0 | AR10: 0 | AS10: 0 | AT10: =rIngItem!AA10 -> 0 | AU10: =rIngItem!AC10 -> 0 | AV10: =rIngItem!AE10 -> 0 | AW10: =rIngItem!AG10 -> 0 | AX10: 0 | AY10: =rIngItem!L10 -> 0 | AZ10: =rIngItem!V10 -> 0 | BA10: =rIngItem!W10 -> 2 | BB10: =rIngItem!X10 -> 0 | BC10: =rIngItem!Y10 -> 0 | BD10: 0
A11: =rIngItem!A11 -> iibba09 | B11: =rIngItem!E11 -> Aqua Parsal WristletA | C11: =rIngItem!C11 -> 700908 | D11: =rIngItem!D11 -> 62 | E11: =rIngItem!I11 -> 11000000 | F11: 9 | G11: =rIngItem!M11 -> 1 | H11: 0 | I11: =rIngItem!N11 -> 60 | J11: =rIngItem!O11 -> 0 | K11: =rIngItem!P11 -> 0 | L11: =rIngItem!R11 -> 0 | M11: =rIngItem!Q11 -> 0 | N11: =rIngItem!S11 -> 1200 | O11: =rIngItem!AI11 -> 1 | P11: =rIngItem!AH11 -> 1 | Q11: =rIngItem!AJ11 -> 1 | R11: =rIngItem!AK11 -> 1 | S11: 122 | T11: =rIngItem!B11 -> 1 | U11: =rIngItem!AN11 -> 0 | V11: =rIngItem!AO11 -> 0 | W11: =rIngItem!K11 -> -1 | X11: =rIngItem!G11 -> 0 | Y11: 0 | Z11: 0 | AA11: 0 | AB11: 0 | AC11: =rIngItem!J11 -> 1 | AD11: 0 | AE11: 0 | AF11: 0 | AG11: 0 | AH11: 0 | AI11: 0 | AJ11: 0 | AK11: 0 | AL11: =IF(AM11=0,0,IF(AN11=0,1,IF(AO11=0,2,IF(AP11=0,3,4)))) -> 0 | AM11: =rIngItem!Z11 -> 0 | AN11: =rIngItem!AB11 -> 0 | AO11: =rIngItem!AD11 -> 0 | AP11: =rIngItem!AF11 -> 0 | AQ11: 0 | AR11: 0 | AS11: 0 | AT11: =rIngItem!AA11 -> 0 | AU11: =rIngItem!AC11 -> 0 | AV11: =rIngItem!AE11 -> 0 | AW11: =rIngItem!AG11 -> 0 | AX11: 0 | AY11: =rIngItem!L11 -> 0 | AZ11: =rIngItem!V11 -> 0 | BA11: =rIngItem!W11 -> 3 | BB11: =rIngItem!X11 -> 0 | BC11: =rIngItem!Y11 -> 0 | BD11: 0
A12: =rIngItem!A12 -> iibba10 | B12: =rIngItem!E12 -> Aqua Parsal WristletB | C12: =rIngItem!C12 -> 700909 | D12: =rIngItem!D12 -> 62 | E12: =rIngItem!I12 -> 11000000 | F12: 9 | G12: =rIngItem!M12 -> 1 | H12: 0 | I12: =rIngItem!N12 -> 60 | J12: =rIngItem!O12 -> 0 | K12: =rIngItem!P12 -> 0 | L12: =rIngItem!R12 -> 0 | M12: =rIngItem!Q12 -> 0 | N12: =rIngItem!S12 -> 1200 | O12: =rIngItem!AI12 -> 1 | P12: =rIngItem!AH12 -> 1 | Q12: =rIngItem!AJ12 -> 1 | R12: =rIngItem!AK12 -> 1 | S12: 123 | T12: =rIngItem!B12 -> 1 | U12: =rIngItem!AN12 -> 0 | V12: =rIngItem!AO12 -> 0 | W12: =rIngItem!K12 -> -1 | X12: =rIngItem!G12 -> 0 | Y12: 0 | Z12: 0 | AA12: 0 | AB12: 0 | AC12: =rIngItem!J12 -> 1 | AD12: 0 | AE12: 0 | AF12: 0 | AG12: 0 | AH12: 0 | AI12: 0 | AJ12: 0 | AK12: 0 | AL12: =IF(AM12=0,0,IF(AN12=0,1,IF(AO12=0,2,IF(AP12=0,3,4)))) -> 0 | AM12: =rIngItem!Z12 -> 0 | AN12: =rIngItem!AB12 -> 0 | AO12: =rIngItem!AD12 -> 0 | AP12: =rIngItem!AF12 -> 0 | AQ12: 0 | AR12: 0 | AS12: 0 | AT12: =rIngItem!AA12 -> 0 | AU12: =rIngItem!AC12 -> 0 | AV12: =rIngItem!AE12 -> 0 | AW12: =rIngItem!AG12 -> 0 | AX12: 0 | AY12: =rIngItem!L12 -> 0 | AZ12: =rIngItem!V12 -> 0 | BA12: =rIngItem!W12 -> 3 | BB12: =rIngItem!X12 -> 0 | BC12: =rIngItem!Y12 -> 0 | BD12: 0
A13: =rIngItem!A13 -> iibba11 | B13: =rIngItem!E13 -> Aqua Parsal WristletC | C13: =rIngItem!C13 -> 70090A | D13: =rIngItem!D13 -> 62 | E13: =rIngItem!I13 -> 11000000 | F13: 9 | G13: =rIngItem!M13 -> 1 | H13: 0 | I13: =rIngItem!N13 -> 60 | J13: =rIngItem!O13 -> 0 | K13: =rIngItem!P13 -> 0 | L13: =rIngItem!R13 -> 0 | M13: =rIngItem!Q13 -> 0 | N13: =rIngItem!S13 -> 1200 | O13: =rIngItem!AI13 -> 1 | P13: =rIngItem!AH13 -> 1 | Q13: =rIngItem!AJ13 -> 1 | R13: =rIngItem!AK13 -> 1 | S13: 124 | T13: =rIngItem!B13 -> 1 | U13: =rIngItem!AN13 -> 0 | V13: =rIngItem!AO13 -> 0 | W13: =rIngItem!K13 -> -1 | X13: =rIngItem!G13 -> 0 | Y13: 0 | Z13: 0 | AA13: 0 | AB13: 0 | AC13: =rIngItem!J13 -> 1 | AD13: 0 | AE13: 0 | AF13: 0 | AG13: 0 | AH13: 0 | AI13: 0 | AJ13: 0 | AK13: 0 | AL13: =IF(AM13=0,0,IF(AN13=0,1,IF(AO13=0,2,IF(AP13=0,3,4)))) -> 0 | AM13: =rIngItem!Z13 -> 0 | AN13: =rIngItem!AB13 -> 0 | AO13: =rIngItem!AD13 -> 0 | AP13: =rIngItem!AF13 -> 0 | AQ13: 0 | AR13: 0 | AS13: 0 | AT13: =rIngItem!AA13 -> 0 | AU13: =rIngItem!AC13 -> 0 | AV13: =rIngItem!AE13 -> 0 | AW13: =rIngItem!AG13 -> 0 | AX13: 0 | AY13: =rIngItem!L13 -> 0 | AZ13: =rIngItem!V13 -> 0 | BA13: =rIngItem!W13 -> 4 | BB13: =rIngItem!X13 -> 0 | BC13: =rIngItem!Y13 -> 0 | BD13: 0
A14: =rIngItem!A14 -> iibba12 | B14: =rIngItem!E14 -> Aqua Parsal WristletD | C14: =rIngItem!C14 -> 70090B | D14: =rIngItem!D14 -> 62 | E14: =rIngItem!I14 -> 11000000 | F14: 9 | G14: =rIngItem!M14 -> 1 | H14: 0 | I14: =rIngItem!N14 -> 60 | J14: =rIngItem!O14 -> 0 | K14: =rIngItem!P14 -> 0 | L14: =rIngItem!R14 -> 0 | M14: =rIngItem!Q14 -> 0 | N14: =rIngItem!S14 -> 1200 | O14: =rIngItem!AI14 -> 1 | P14: =rIngItem!AH14 -> 1 | Q14: =rIngItem!AJ14 -> 1 | R14: =rIngItem!AK14 -> 1 | S14: 125 | T14: =rIngItem!B14 -> 1 | U14: =rIngItem!AN14 -> 0 | V14: =rIngItem!AO14 -> 0 | W14: =rIngItem!K14 -> -1 | X14: =rIngItem!G14 -> 0 | Y14: 0 | Z14: 0 | AA14: 0 | AB14: 0 | AC14: =rIngItem!J14 -> 1 | AD14: 0 | AE14: 0 | AF14: 0 | AG14: 0 | AH14: 0 | AI14: 0 | AJ14: 0 | AK14: 0 | AL14: =IF(AM14=0,0,IF(AN14=0,1,IF(AO14=0,2,IF(AP14=0,3,4)))) -> 0 | AM14: =rIngItem!Z14 -> 0 | AN14: =rIngItem!AB14 -> 0 | AO14: =rIngItem!AD14 -> 0 | AP14: =rIngItem!AF14 -> 0 | AQ14: 0 | AR14: 0 | AS14: 0 | AT14: =rIngItem!AA14 -> 0 | AU14: =rIngItem!AC14 -> 0 | AV14: =rIngItem!AE14 -> 0 | AW14: =rIngItem!AG14 -> 0 | AX14: 0 | AY14: =rIngItem!L14 -> 0 | AZ14: =rIngItem!V14 -> 0 | BA14: =rIngItem!W14 -> 5 | BB14: =rIngItem!X14 -> 0 | BC14: =rIngItem!Y14 -> 0 | BD14: 0
... A1592: =rIngItem!A1592 -> iicsa32 | B1592: =rIngItem!E1592 -> Solo Boss Ring | C1592: =rIngItem!C1592 -> A00947 | D1592: =rIngItem!D1592 -> 215 | E1592: =rIngItem!I1592 -> 11111000 | F1592: 9 | G1592: =rIngItem!M1592 -> 0 | H1592: 0 | I1592: =rIngItem!N1592 -> 1 | J1592: =rIngItem!O1592 -> 0 | K1592: =rIngItem!P1592 -> 0 | L1592: =rIngItem!R1592 -> 0 | M1592: =rIngItem!Q1592 -> 0 | N1592: =rIngItem!S1592 -> 20000 | O1592: =rIngItem!AI1592 -> 1 | P1592: =rIngItem!AH1592 -> 1 | Q1592: =rIngItem!AJ1592 -> 1 | R1592: =rIngItem!AK1592 -> 1 | S1592: 1510 | T1592: =rIngItem!B1592 -> 1 | U1592: =rIngItem!AN1592 -> 1 | V1592: =rIngItem!AO1592 -> 1 | W1592: =rIngItem!K1592 -> -1 | X1592: =rIngItem!G1592 -> 7 | Y1592: 0 | Z1592: 0 | AA1592: 0 | AB1592: 0 | AC1592: =rIngItem!J1592 -> 1 | AD1592: 0 | AE1592: 0 | AF1592: 0 | AG1592: 0 | AH1592: 0 | AI1592: 0 | AJ1592: 0 | AK1592: 0 | AL1592: =IF(AM1592=0,0,IF(AN1592=0,1,IF(AO1592=0,2,IF(AP1592=0,3,4)))) -> 3 | AM1592: =rIngItem!Z1592 -> 6 | AN1592: =rIngItem!AB1592 -> 7 | AO1592: =rIngItem!AD1592 -> 5 | AP1592: =rIngItem!AF1592 -> 0 | AQ1592: 0 | AR1592: 0 | AS1592: 0 | AT1592: =rIngItem!AA1592 -> 0.1 | AU1592: =rIngItem!AC1592 -> 0.10000001 | AV1592: =rIngItem!AE1592 -> 0.050000006 | AW1592: =rIngItem!AG1592 -> 0 | AX1592: 0 | AY1592: =rIngItem!L1592 -> 0 | AZ1592: =rIngItem!V1592 -> 4 | BA1592: =rIngItem!W1592 -> 4 | BB1592: =rIngItem!X1592 -> 4 | BC1592: =rIngItem!Y1592 -> 4 | BD1592: 0

Sheet 9desc
A1: dword | B1: text | C1: END
A2: Count | B2: descript
A3: 0 | B3: Accessary with skull crest of revival. it includes happiness of liberated exiles from outkast's Land.
A4: 1 | B4: Accessary with skull crest of revival. it includes happiness of liberated exiles from outkast's Land.
A5: 2 | B5: Accessary with skull crest of revival. it includes happiness of liberated exiles from outkast's Land.
A6: 3 | B6: Accessary with skull crest of Death. it includes vindictive spirit killed in outkast's Land.
A7: 4 | B7: Accessary with skull crest of Death. it includes vindictive spirit killed in outkast's Land.
A8: 5 | B8: Accessary with skull crest of Death. it includes vindictive spirit killed in outkast's Land.
A9: 6 | B9: Accessories that possess the force of [Hora Grave Stone], a living weapon, made after infinite medical experiment on the living body by BaalHamon. If used with the storm crest, it displays more powerful force. One of the 8 crest of forces smelted in the b
A10: 7 | B10: Accessories that possess the force of [Hora Grave Stone], a living weapon, made after infinite medical experiment on the living body by BaalHamon. If used with the storm crest, it displays more powerful force. One of the 8 crest of forces smelted in the b
A11: 8 | B11: Accessories that possess the force of [Hora Grave Stone], a living weapon, made after infinite medical experiment on the living body by BaalHamon. If used with the storm crest, it displays more powerful force. One of the 8 crest of forces smelted in the b
A12: 9 | B12: Accessories that possess the force of [Hora Grave Stone], a living weapon, made after infinite medical experiment on the living body by BaalHamon. If used with the storm crest, it displays more powerful force. One of the 8 crest of forces smelted in the b
A13: 10 | B13: Accessories adornmented with spirit crest which is one of the 8 crest of forces made with sorrow, scream, and grudge of those who were sacrificed by BaalHamon. If used with the blood crest, it displays more powerful force. It is made with [Ring of La Mant
A14: 11 | B14: Accessories adornmented with spirit crest which is one of the 8 crest of forces made with sorrow, scream, and grudge of those who were sacrificed by BaalHamon. If used with the blood crest, it displays more powerful force. It is made with [Ring of La Mant
... A62: 59 | B62: Crest of force smelted for Baalmon itself, made with the most powerful broken pieces from [Ring of La Mantulas]. It is adornmented with crest of control which controls the other crests. It possesses the force and will to oppose BaalHamon's own master, [La
A63: 60
A64: 61
A65: 62
A66: 63
A67: 64
A68: 65
A69: 66
A70: 67
A71: 68
A72: 69
A73: 70
A74: 71
... A116: 113
A117: 114 | B117: Fire resistance wristlet for Bellato.
A118: 115 | B118: Fire resistance wristlet for Bellato.
A119: 116 | B119: Fire resistance wristlet for Bellato.
A120: 117 | B120: Fire resistance wristlet for Bellato.
A121: 118 | B121: Fire resistance wristlet for Bellato.
A122: 119 | B122: Fire resistance wristlet for Bellato.
A123: 120 | B123: Fire resistance wristlet for Bellato.
A124: 121 | B124: Water resistance wristlet for Bellato.
A125: 122 | B125: Water resistance wristlet for Bellato.
A126: 123 | B126: Water resistance wristlet for Bellato.
A127: 124 | B127: Water resistance wristlet for Bellato.
A128: 125 | B128: Water resistance wristlet for Bellato.
...
